<?xml version='1.0' encoding='utf-8'?>
<robot xmlns:xacro="http://www.ros.org/wiki/xacro" name="Assem1">

    <xacro:include filename="grasper.xacro" />

    <link name="dummy_link" />

    <joint name="dummy_joint" type="fixed">
        <parent link="dummy_link" />
        <child link="base" />
        <origin xyz="0 0 0" rpy="0 0 0" />
    </joint>

    <link name="base">
        <inertial>
            <origin xyz="0.020317199348187365 0.07751842746519011 -5.546945197177871e-05" rpy="0.0 0.0 0.0" />
            <mass value="109.66794164984553" />
            <inertia ixx="1.1056233078423974" iyy="1.5128905242947293" izz="1.0480698869126281" ixy="-0.13072794340887023" iyz="0.0005527238695286845" ixz="-0.00041991712603643185" />
        </inertial>
        <visual name="base_visual">
            <origin xyz="0.0 0.0 0.0" rpy="0.0 0.0 0.0" />
            <geometry>
                <mesh filename="package://assem1_description/meshes/base.stl" scale="0.001 0.001 0.001" />
            </geometry>
        </visual>
        <collision name="base_collision">
            <origin xyz="0.0 0.0 0.0" rpy="0.0 0.0 0.0" />
            <geometry>
                <mesh filename="package://assem1_description/meshes/base.stl" scale="0.001 0.001 0.001" />
            </geometry>
        </collision>
    </link>

    <joint name="joint1" type="continuous">
        <parent link="base" />
        <child link="link1" />
        <origin xyz="0 0 0" rpy="0 0 0" />
        <axis xyz="0 0 1" />
    </joint>

    <link name="link1">
        <inertial>
            <origin xyz="1.4499742760631928e-09 0.20439626220341348 -0.00856662164364463" rpy="0.0 0.0 0.0" />
            <mass value="60.43163697204141" />
            <inertia ixx="1.3133855062071103" iyy="0.17097379735086232" izz="1.2915963352803819" ixy="-2.0051005578114456e-09" iyz="0.1002042920925576" ixz="-4.561932301822046e-08" />
        </inertial>
        <visual name="link1_visual">
            <origin xyz="0.0 0.0 0.0" rpy="0.0 0.0 0.0" />
            <geometry>
                <mesh filename="package://assem1_description/meshes/link1.stl" scale="0.001 0.001 0.001" />
            </geometry>
        </visual>
        <collision name="link1_collision">
            <origin xyz="0.0 0.0 0.0" rpy="0.0 0.0 0.0" />
            <geometry>
                <mesh filename="package://assem1_description/meshes/link1.stl" scale="0.001 0.001 0.001" />
            </geometry>
        </collision>
    </link>

    <joint name="joint2" type="continuous">
        <parent link="link1" />
        <child link="link2" />
        <origin xyz="0 0 0" rpy="0 0 0" />
        <axis xyz="0 0 1" />
    </joint>

    <link name="link2">
        <inertial>
            <origin xyz="-0.13533518022695862 0.09502469900607462 4.607453042704268e-08" rpy="0.0 0.0 0.0" />
            <mass value="50.71916135857823" />
            <inertia ixx="0.6331260751668601" iyy="0.41193174988409015" izz="0.939457835636486" ixy="0.3017027808717332" iyz="-4.884478082833876e-07" ixz="3.390666361569039e-08" />
        </inertial>
        <visual name="link2_visual">
            <origin xyz="0.0 0.0 0.0" rpy="0.0 0.0 0.0" />
            <geometry>
                <mesh filename="package://assem1_description/meshes/link2.stl" scale="0.001 0.001 0.001" />
            </geometry>
        </visual>
        <collision name="link2_collision">
            <origin xyz="0.0 0.0 0.0" rpy="0.0 0.0 0.0" />
            <geometry>
                <mesh filename="package://assem1_description/meshes/link2.stl" scale="0.001 0.001 0.001" />
            </geometry>
        </collision>
    </link>

    <joint name="joint3" type="continuous">
        <parent link="link2" />
        <child link="Part4" />
        <origin xyz="0 0 0" rpy="0 0 0" />
        <axis xyz="0 0 1" />
    </joint>

    <link name="Part4">
        <inertial>
            <origin xyz="0.08170267056687046 0.14175872118472854 -9.199890849131975e-12" rpy="0.0 0.0 0.0" />
            <mass value="66.10082637305962" />
            <inertia ixx="0.5677755384283207" iyy="0.7431560289299646" izz="1.0719148976055057" ixy="-0.314456861788035" iyz="3.540101545240759e-11" ixz="1.0181669396480686e-10" />
        </inertial>
        <visual name="Part4_visual">
            <origin xyz="0.0 0.0 0.0" rpy="0.0 0.0 0.0" />
            <geometry>
                <mesh filename="package://assem1_description/meshes/Part4.stl" scale="0.001 0.001 0.001" />
            </geometry>
        </visual>
        <collision name="Part4_collision">
            <origin xyz="0.0 0.0 0.0" rpy="0.0 0.0 0.0" />
            <geometry>
                <mesh filename="package://assem1_description/meshes/Part4.stl" scale="0.001 0.001 0.001" />
            </geometry>
        </collision>
    </link>

    <joint name="joint4" type="continuous">
        <parent link="Part4" />
        <child link="link5" />
        <origin xyz="0 0 0" rpy="0 0 0" />
        <axis xyz="0 0 1" />
    </joint>

    <link name="link5">
        <inertial>
            <origin xyz="0.09520546142961062 0.16793012105171246 -1.6779888539576737e-05" rpy="0.0 0.0 0.0" />
            <mass value="55.0547921831384" />
            <inertia ixx="0.283525879699291" iyy="0.6095219189318408" izz="0.7049998656294733" ixy="-0.16809119947526294" iyz="1.026462630249192e-05" ixz="0.0001502861219719112" />
        </inertial>
        <visual name="link5_visual">
            <origin xyz="0.0 0.0 0.0" rpy="0.0 0.0 0.0" />
            <geometry>
                <mesh filename="package://assem1_description/meshes/link5.stl" scale="0.001 0.001 0.001" />
            </geometry>
        </visual>
        <collision name="link5_collision">
            <origin xyz="0.0 0.0 0.0" rpy="0.0 0.0 0.0" />
            <geometry>
                <mesh filename="package://assem1_description/meshes/link5.stl" scale="0.001 0.001 0.001" />
            </geometry>
        </collision>
    </link>

    <joint name="joint5" type="continuous">
        <parent link="link5" />
        <child link="link6" />
        <origin xyz="0 0 0" rpy="0 0 0" />
        <axis xyz="0 0 1" />
    </joint>

    <link name="link6">
        <inertial>
            <origin xyz="-0.01124919532726499 0.10533234009618142 -2.804579866955148e-10" rpy="0.0 0.0 0.0" />
            <mass value="32.785337487447315" />
            <inertia ixx="0.4499773664575174" iyy="0.07778918624439538" izz="0.4532559874202917" ixy="0.05239847675509361" iyz="-2.7992584986091806e-10" ixz="2.732835208130169e-10" />
        </inertial>
        <visual name="link6_visual">
            <origin xyz="0.0 0.0 0.0" rpy="0.0 0.0 0.0" />
            <geometry>
                <mesh filename="package://assem1_description/meshes/link6.stl" scale="0.001 0.001 0.001" />
            </geometry>
        </visual>
        <collision name="link6_collision">
            <origin xyz="0.0 0.0 0.0" rpy="0.0 0.0 0.0" />
            <geometry>
                <mesh filename="package://assem1_description/meshes/link6.stl" scale="0.001 0.001 0.001" />
            </geometry>
        </collision>
    </link>

    <!-- Attach the grasper to the final link -->
    <xacro:laproscopic_grasper parent="link6">
        <origin xyz="0 0 0" rpy="0 0 0"/>
    </xacro:laproscopic_grasper>

</robot>
