<?xml version="1.0"?>
<robot xmlns:xacro="http://www.ros.org/wiki/xacro">
  <material name="surgical_steel"> <color rgba="0.75 0.75 0.80 1.0"/> </material>
  <material name="dark_metal">     <color rgba="0.18 0.18 0.22 1.0"/> </material>
  <material name="sensor_yellow">  <color rgba="1.0  0.85 0.0  1.0"/> </material>
  <material name="tip_blue">       <color rgba="0.05 0.35 0.85 1.0"/> </material>
  <material name="finger_color">   <color rgba="0.15 0.55 0.95 1.0"/> </material>
  <material name="finger_tip_col"> <color rgba="0.95 0.85 0.10 1.0"/> </material>
  <material name="wrist_color">    <color rgba="0.55 0.60 0.70 1.0"/> </material>
  <material name="scara_orange">   <color rgba="0.85 0.40 0.05 1.0"/> </material>
  <xacro:macro name="laproscopic_grasper" params="parent *origin">
    <joint name="grasper_attach_joint" type="continuous">
      <parent link="${parent}"/>
      <child link="trocar_shaft"/>
      <xacro:insert_block name="origin"/>
      <axis xyz="0 0 1"/>
      <limit lower="-3.14159" upper="3.14159" effort="10" velocity="1.0"/>
    </joint>
  <link name="trocar_shaft">
    <visual>
      <origin xyz="0 0 -0.12" rpy="0 0 0"/>
      <geometry><cylinder radius="0.007" length="0.24"/></geometry>
      <material name="tip_blue"/>
    </visual>
    <collision>
      <origin xyz="0 0 -0.12" rpy="0 0 0"/>
      <geometry><cylinder radius="0.007" length="0.24"/></geometry>
    </collision>
    <inertial>
      <mass value="0.08"/>
      <inertia ixx="0.0006" ixy="0" ixz="0" iyy="0.0006" iyz="0" izz="0.000001"/>
    </inertial>
  </link>

  <!-- ================================================================== -->
  <!--  FORCE/TORQUE SENSOR RING                                         -->
  <!-- ================================================================== -->
  <link name="force_sensor_ring">
    <visual>
      <origin xyz="0 0 0" rpy="0 0 0"/>
      <geometry><cylinder radius="0.013" length="0.015"/></geometry>
      <material name="sensor_yellow"/>
    </visual>
    <collision>
      <origin xyz="0 0 0" rpy="0 0 0"/>
      <geometry><cylinder radius="0.013" length="0.015"/></geometry>
    </collision>
    <inertial>
      <mass value="0.02"/>
      <inertia ixx="0.00001" ixy="0" ixz="0" iyy="0.00001" iyz="0" izz="0.000002"/>
    </inertial>
  </link>

  <joint name="sensor_ring_joint" type="fixed">
    <parent link="trocar_shaft"/>
    <child link="force_sensor_ring"/>
    <origin xyz="0 0 -0.04" rpy="0 0 0"/>
  </joint>

  <!-- ================================================================== -->
  <!--  JOINT 5 - WRIST PITCH                                            -->
  <!--  Pitches the entire grasper head +/-45 deg for approach angle.    -->
  <!-- ================================================================== -->
  <joint name="joint5_wrist_pitch" type="revolute">
    <parent link="trocar_shaft"/>
    <child link="wrist_link"/>
    <origin xyz="0 0 -0.24" rpy="0 0 0"/>
    <axis xyz="0 1 0"/>
    <limit lower="-0.785" upper="0.785" effort="8" velocity="0.8"/>
    <dynamics damping="0.15" friction="0.03"/>
  </joint>

  <!-- ================================================================== -->
  <!--  WRIST LINK                                                        -->
  <!-- ================================================================== -->
  <link name="wrist_link">
    <visual>
      <origin xyz="0 0 -0.018" rpy="0 0 0"/>
      <geometry><cylinder radius="0.011" length="0.036"/></geometry>
      <material name="wrist_color"/>
    </visual>
    <collision>
      <origin xyz="0 0 -0.018" rpy="0 0 0"/>
      <geometry><cylinder radius="0.011" length="0.036"/></geometry>
    </collision>
    <inertial>
      <mass value="0.04"/>
      <inertia ixx="0.00003" ixy="0" ixz="0" iyy="0.00003" iyz="0" izz="0.000002"/>
    </inertial>
  </link>

  <!-- ================================================================== -->
  <!--  FINGER BASE (fixed hub between wrist and fingers)                -->
  <!-- ================================================================== -->
  <link name="finger_base">
    <visual>
      <origin xyz="0 0 -0.014" rpy="0 0 0"/>
      <geometry><box size="0.030 0.022 0.028"/></geometry>
      <material name="surgical_steel"/>
    </visual>
    <collision>
      <origin xyz="0 0 -0.014" rpy="0 0 0"/>
      <geometry><box size="0.030 0.022 0.028"/></geometry>
    </collision>
    <inertial>
      <mass value="0.05"/>
      <inertia ixx="0.00004" ixy="0" ixz="0" iyy="0.00004" iyz="0" izz="0.000003"/>
    </inertial>
  </link>

  <joint name="finger_base_joint" type="fixed">
    <parent link="wrist_link"/>
    <child link="finger_base"/>
    <origin xyz="0 0 -0.036" rpy="0 0 0"/>
  </joint>

  <!-- ================================================================== -->
  <!--  FINGER LEFT - PROXIMAL PHALANX                                   -->
  <!--  0 = closed, +0.55 rad = fully open.                              -->
  <!-- ================================================================== -->
  <joint name="finger_left_proximal_joint" type="revolute">
    <parent link="finger_base"/>
    <child link="finger_left_proximal"/>
    <origin xyz="0.007 0.009 -0.028" rpy="0 0 0"/>
    <axis xyz="0 1 0"/>
    <limit lower="0.0" upper="0.55" effort="6" velocity="1.2"/>
    <dynamics damping="0.08" friction="0.02"/>
  </joint>

  <link name="finger_left_proximal">
    <visual>
      <origin xyz="0.005 0.004 -0.016" rpy="0 0.18 0"/>
      <geometry><box size="0.007 0.008 0.032"/></geometry>
      <material name="finger_color"/>
    </visual>
    <collision>
      <origin xyz="0.005 0.004 -0.016" rpy="0 0.18 0"/>
      <geometry><box size="0.007 0.008 0.032"/></geometry>
    </collision>
    <inertial>
      <mass value="0.012"/>
      <inertia ixx="0.000008" ixy="0" ixz="0" iyy="0.000008" iyz="0" izz="0.000001"/>
    </inertial>
  </link>

  <!-- ================================================================== -->
  <!--  FINGER LEFT - DISTAL PHALANX (tip)                               -->
  <!-- ================================================================== -->
  <joint name="finger_left_distal_joint" type="revolute">
    <parent link="finger_left_proximal"/>
    <child link="finger_left_distal"/>
    <origin xyz="0.009 0.005 -0.030" rpy="0 0 0"/>
    <axis xyz="0 1 0"/>
    <limit lower="0.0" upper="0.40" effort="4" velocity="1.2"/>
    <dynamics damping="0.05" friction="0.01"/>
  </joint>

  <link name="finger_left_distal">
    <visual>
      <origin xyz="0.004 0.002 -0.010" rpy="0 0.12 0"/>
      <geometry><box size="0.006 0.007 0.020"/></geometry>
      <material name="finger_tip_col"/>
    </visual>
    <collision>
      <origin xyz="0.004 0.002 -0.010" rpy="0 0.12 0"/>
      <geometry><box size="0.006 0.007 0.020"/></geometry>
    </collision>
    <inertial>
      <mass value="0.006"/>
      <inertia ixx="0.000003" ixy="0" ixz="0" iyy="0.000003" iyz="0" izz="0.0000005"/>
    </inertial>
  </link>

  <!-- Left distal contact sensor -->
  <link name="jaw_left_sensor">
    <visual>
      <origin xyz="0 0 0" rpy="0 0 0"/>
      <geometry><box size="0.003 0.005 0.004"/></geometry>
      <material name="sensor_yellow"/>
    </visual>
    <collision>
      <origin xyz="0 0 0" rpy="0 0 0"/>
      <geometry><box size="0.003 0.005 0.004"/></geometry>
    </collision>
    <inertial>
      <mass value="0.001"/>
      <inertia ixx="0.000001" ixy="0" ixz="0" iyy="0.000001" iyz="0" izz="0.000001"/>
    </inertial>
  </link>

  <joint name="jaw_left_sensor_joint" type="fixed">
    <parent link="finger_left_distal"/>
    <child link="jaw_left_sensor"/>
    <origin xyz="0.004 0.002 -0.018" rpy="0 0 0"/>
  </joint>

  <!-- ================================================================== -->
  <!--  FINGER RIGHT - PROXIMAL PHALANX (mirror of left)                 -->
  <!--  Opens in -Y direction.                                            -->
  <!-- ================================================================== -->
  <joint name="finger_right_proximal_joint" type="revolute">
    <parent link="finger_base"/>
    <child link="finger_right_proximal"/>
    <origin xyz="0.007 -0.009 -0.028" rpy="0 0 0"/>
    <axis xyz="0 1 0"/>
    <limit lower="-0.55" upper="0.0" effort="6" velocity="1.2"/>
    <dynamics damping="0.08" friction="0.02"/>
  </joint>

  <link name="finger_right_proximal">
    <visual>
      <origin xyz="0.005 -0.004 -0.016" rpy="0 -0.18 0"/>
      <geometry><box size="0.007 0.008 0.032"/></geometry>
      <material name="finger_color"/>
    </visual>
    <collision>
      <origin xyz="0.005 -0.004 -0.016" rpy="0 -0.18 0"/>
      <geometry><box size="0.007 0.008 0.032"/></geometry>
    </collision>
    <inertial>
      <mass value="0.012"/>
      <inertia ixx="0.000008" ixy="0" ixz="0" iyy="0.000008" iyz="0" izz="0.000001"/>
    </inertial>
  </link>

  <!-- ================================================================== -->
  <!--  FINGER RIGHT - DISTAL PHALANX (tip)                              -->
  <!-- ================================================================== -->
  <joint name="finger_right_distal_joint" type="revolute">
    <parent link="finger_right_proximal"/>
    <child link="finger_right_distal"/>
    <origin xyz="0.009 -0.005 -0.030" rpy="0 0 0"/>
    <axis xyz="0 1 0"/>
    <limit lower="-0.40" upper="0.0" effort="4" velocity="1.2"/>
    <dynamics damping="0.05" friction="0.01"/>
  </joint>

  <link name="finger_right_distal">
    <visual>
      <origin xyz="0.004 -0.002 -0.010" rpy="0 -0.12 0"/>
      <geometry><box size="0.006 0.007 0.020"/></geometry>
      <material name="finger_tip_col"/>
    </visual>
    <collision>
      <origin xyz="0.004 -0.002 -0.010" rpy="0 -0.12 0"/>
      <geometry><box size="0.006 0.007 0.020"/></geometry>
    </collision>
    <inertial>
      <mass value="0.006"/>
      <inertia ixx="0.000003" ixy="0" ixz="0" iyy="0.000003" iyz="0" izz="0.0000005"/>
    </inertial>
  </link>

  <!-- Right distal contact sensor -->
  <link name="jaw_right_sensor">
    <visual>
      <origin xyz="0 0 0" rpy="0 0 0"/>
      <geometry><box size="0.003 0.005 0.004"/></geometry>
      <material name="sensor_yellow"/>
    </visual>
    <collision>
      <origin xyz="0 0 0" rpy="0 0 0"/>
      <geometry><box size="0.003 0.005 0.004"/></geometry>
    </collision>
    <inertial>
      <mass value="0.001"/>
      <inertia ixx="0.000001" ixy="0" ixz="0" iyy="0.000001" iyz="0" izz="0.000001"/>
    </inertial>
  </link>

  <joint name="jaw_right_sensor_joint" type="fixed">
    <parent link="finger_right_distal"/>
    <child link="jaw_right_sensor"/>
    <origin xyz="0.004 -0.002 -0.018" rpy="0 0 0"/>
  </joint>

  <!-- ================================================================== -->
  <!--  GEAR MECHANISM - Rack-and-Pinion Grasper Drive (visual only)     -->
  <!-- ================================================================== -->

  <!-- Central drive pinion gear disc -->
  <link name="drive_pinion">
    <visual>
      <origin xyz="0 0 0" rpy="1.5708 0 0"/>
      <geometry><cylinder radius="0.013" length="0.007"/></geometry>
      <material name="dark_metal"/>
    </visual>
    <!-- Gear teeth (cosmetic boxes around pinion) -->
    <visual>
      <origin xyz=" 0.013 0     0.0035" rpy="0 0 0"/>
      <geometry><box size="0.004 0.003 0.007"/></geometry>
      <material name="sensor_yellow"/>
    </visual>
    <visual>
      <origin xyz="-0.013 0     0.0035" rpy="0 0 0"/>
      <geometry><box size="0.004 0.003 0.007"/></geometry>
      <material name="sensor_yellow"/>
    </visual>
    <visual>
      <origin xyz="0  0.013     0.0035" rpy="0 0 0"/>
      <geometry><box size="0.003 0.004 0.007"/></geometry>
      <material name="sensor_yellow"/>
    </visual>
    <visual>
      <origin xyz="0 -0.013     0.0035" rpy="0 0 0"/>
      <geometry><box size="0.003 0.004 0.007"/></geometry>
      <material name="sensor_yellow"/>
    </visual>
    <visual>
      <origin xyz=" 0.009  0.009 0.0035" rpy="0 0 0.785"/>
      <geometry><box size="0.004 0.003 0.007"/></geometry>
      <material name="sensor_yellow"/>
    </visual>
    <visual>
      <origin xyz="-0.009  0.009 0.0035" rpy="0 0 0.785"/>
      <geometry><box size="0.004 0.003 0.007"/></geometry>
      <material name="sensor_yellow"/>
    </visual>
    <visual>
      <origin xyz=" 0.009 -0.009 0.0035" rpy="0 0 0.785"/>
      <geometry><box size="0.004 0.003 0.007"/></geometry>
      <material name="sensor_yellow"/>
    </visual>
    <visual>
      <origin xyz="-0.009 -0.009 0.0035" rpy="0 0 0.785"/>
      <geometry><box size="0.004 0.003 0.007"/></geometry>
      <material name="sensor_yellow"/>
    </visual>
    <inertial>
      <mass value="0.005"/>
      <inertia ixx="0.000001" ixy="0" ixz="0" iyy="0.000001" iyz="0" izz="0.000002"/>
    </inertial>
  </link>

  <joint name="drive_pinion_joint" type="fixed">
    <parent link="finger_base"/>
    <child  link="drive_pinion"/>
    <origin xyz="0.007 0 -0.005" rpy="0 0 0"/>
  </joint>

  <!-- Worm screw input at wrist/shaft junction -->
  <link name="worm_screw">
    <visual>
      <origin xyz="0 0 0.012" rpy="0 0 0"/>
      <geometry><cylinder radius="0.005" length="0.024"/></geometry>
      <material name="dark_metal"/>
    </visual>
    <visual>
      <origin xyz=" 0.005 0     0.006" rpy="0  0.5 0"/>
      <geometry><box size="0.002 0.008 0.004"/></geometry>
      <material name="sensor_yellow"/>
    </visual>
    <visual>
      <origin xyz="0      0.005 0.012" rpy=" 0.5 0 0"/>
      <geometry><box size="0.008 0.002 0.004"/></geometry>
      <material name="sensor_yellow"/>
    </visual>
    <visual>
      <origin xyz="-0.005 0     0.018" rpy="0 -0.5 0"/>
      <geometry><box size="0.002 0.008 0.004"/></geometry>
      <material name="sensor_yellow"/>
    </visual>
    <inertial>
      <mass value="0.003"/>
      <inertia ixx="0.0000005" ixy="0" ixz="0" iyy="0.0000005" iyz="0" izz="0.0000001"/>
    </inertial>
  </link>

  <joint name="worm_screw_joint" type="fixed">
    <parent link="wrist_link"/>
    <child  link="worm_screw"/>
    <origin xyz="0.010 0 -0.010" rpy="0 0 0"/>
  </joint>

  <!-- Left finger rack strip -->
  <link name="rack_left">
    <visual>
      <origin xyz="0 0  0.000" rpy="0 0 0"/>
      <geometry><box size="0.003 0.002 0.005"/></geometry>
      <material name="dark_metal"/>
    </visual>
    <visual>
      <origin xyz="0 0 -0.006" rpy="0 0 0"/>
      <geometry><box size="0.003 0.002 0.005"/></geometry>
      <material name="dark_metal"/>
    </visual>
    <visual>
      <origin xyz="0 0 -0.012" rpy="0 0 0"/>
      <geometry><box size="0.003 0.002 0.005"/></geometry>
      <material name="dark_metal"/>
    </visual>
    <visual>
      <origin xyz="0 0 -0.018" rpy="0 0 0"/>
      <geometry><box size="0.003 0.002 0.005"/></geometry>
      <material name="dark_metal"/>
    </visual>
    <inertial>
      <mass value="0.001"/>
      <inertia ixx="0.0000001" ixy="0" ixz="0" iyy="0.0000001" iyz="0" izz="0.0000001"/>
    </inertial>
  </link>

  <joint name="rack_left_joint" type="fixed">
    <parent link="finger_left_proximal"/>
    <child  link="rack_left"/>
    <origin xyz="-0.001 -0.010 -0.008" rpy="0 0 0"/>
  </joint>

  <!-- Right finger rack strip -->
  <link name="rack_right">
    <visual>
      <origin xyz="0 0  0.000" rpy="0 0 0"/>
      <geometry><box size="0.003 0.002 0.005"/></geometry>
      <material name="dark_metal"/>
    </visual>
    <visual>
      <origin xyz="0 0 -0.006" rpy="0 0 0"/>
      <geometry><box size="0.003 0.002 0.005"/></geometry>
      <material name="dark_metal"/>
    </visual>
    <visual>
      <origin xyz="0 0 -0.012" rpy="0 0 0"/>
      <geometry><box size="0.003 0.002 0.005"/></geometry>
      <material name="dark_metal"/>
    </visual>
    <visual>
      <origin xyz="0 0 -0.018" rpy="0 0 0"/>
      <geometry><box size="0.003 0.002 0.005"/></geometry>
      <material name="dark_metal"/>
    </visual>
    <inertial>
      <mass value="0.001"/>
      <inertia ixx="0.0000001" ixy="0" ixz="0" iyy="0.0000001" iyz="0" izz="0.0000001"/>
    </inertial>
  </link>

  <joint name="rack_right_joint" type="fixed">
    <parent link="finger_right_proximal"/>
    <child  link="rack_right"/>
    <origin xyz="-0.001  0.010 -0.008" rpy="0 0 0"/>
  </joint>
  </xacro:macro>
</robot>
