<?xml version="1.0" ?>
<!-- =================================================================================== -->
<!-- |    This document was autogenerated by xacro from /home/doc/surgical_robot_ws/src/laproscopic_grasper/urdf/laproscopic_grasper.urdf.xacro | -->
<!-- |    EDITING THIS FILE BY HAND IS NOT RECOMMENDED                                 | -->
<!-- =================================================================================== -->
<robot name="kuka_med_with_grasper">
  <material name="Black">
    <color rgba="0.0 0.0 0.0 1.0"/>
  </material>
  <material name="Blue">
    <color rgba="0.0 0.0 0.8 1.0"/>
  </material>
  <material name="Green">
    <color rgba="0.0 0.8 0.0 1.0"/>
  </material>
  <material name="Grey">
    <color rgba="0.4 0.4 0.4 1.0"/>
  </material>
  <material name="Orange">
    <color rgba="1.0 0.4235294117647059 0.0392156862745098 1.0"/>
  </material>
  <material name="Brown">
    <color rgba="0.8705882352941177 0.8117647058823529 0.7647058823529411 1.0"/>
  </material>
  <material name="Red">
    <color rgba="0.8 0.0 0.0 1.0"/>
  </material>
  <material name="White">
    <color rgba="1.0 1.0 1.0 1.0"/>
  </material>
  <!-- ================================================================
       HIGH-FIDELITY TWO-FINGER LAPAROSCOPIC GRASPER (V8 - ULTRA STABLE)
       ================================================================
       Dual Visuals: Simple primitives (guaranteed visibility) + STL Meshes.
       Massive Physics: Mass=0.5 for all joints to ensure Gazebo recognition.
       Merged System: Designed to be included in the main ros2_control block.
       ================================================================ -->
  <!-- World -->
  <link name="world"/>
  <joint name="iiwa14_to_world" type="fixed">
    <parent link="world"/>
    <child link="iiwa14_link0"/>
    <origin rpy="0 0 0" xyz="0 0 0.90"/>
  </joint>
  <link name="iiwa14_link0">
    <inertial>
      <origin rpy="0 0 0" xyz="-0.1 0 0.07"/>
      <mass value="5"/>
      <inertia ixx="0.05" ixy="0" ixz="0" iyy="0.06" iyz="0" izz="0.03"/>
    </inertial>
    <visual>
      <origin rpy="0 0 0" xyz="0 0 0"/>
      <geometry>
        <mesh filename="package://laproscopic_grasper/meshes/iiwa14/visual/link_0.stl"/>
      </geometry>
      <material name="Grey"/>
    </visual>
    <collision>
      <origin rpy="0 0 0" xyz="0 0 0"/>
      <geometry>
        <mesh filename="package://laproscopic_grasper/meshes/iiwa14/collision/link_0.stl"/>
      </geometry>
      <material name="Grey"/>
    </collision>
  </link>
  <joint name="iiwa14_joint1" type="revolute">
    <parent link="iiwa14_link0"/>
    <child link="iiwa14_link1"/>
    <origin rpy="0 0 0" xyz="0 0 0.1575"/>
    <axis xyz="0 0 1"/>
    <limit effort="320" lower="-2.967" upper="2.967" velocity="1.4835"/>
  </joint>
  <link name="iiwa14_link1">
    <inertial>
      <origin rpy="0 0 0" xyz="0 -0.03 0.12"/>
      <mass value="4"/>
      <inertia ixx="0.1" ixy="0" ixz="0" iyy="0.09" iyz="0" izz="0.02"/>
    </inertial>
    <visual>
      <origin rpy="0 0 0" xyz="0 0 0"/>
      <geometry>
        <mesh filename="package://laproscopic_grasper/meshes/iiwa14/visual/link_1.stl"/>
      </geometry>
      <material name="Orange"/>
    </visual>
    <collision>
      <origin rpy="0 0 0" xyz="0 0 0"/>
      <geometry>
        <mesh filename="package://laproscopic_grasper/meshes/iiwa14/collision/link_1.stl"/>
      </geometry>
      <material name="Orange"/>
    </collision>
  </link>
  <joint name="iiwa14_joint2" type="revolute">
    <parent link="iiwa14_link1"/>
    <child link="iiwa14_link2"/>
    <origin rpy="1.57079632679   0 3.14159265358" xyz="0 0 0.2025"/>
    <axis xyz="0 0 1"/>
    <limit effort="320" lower="-2.0944" upper="2.0944" velocity="1.4835"/>
  </joint>
  <link name="iiwa14_link2">
    <inertial>
      <origin rpy="0 0 0" xyz="0.0003 0.059 0.042"/>
      <mass value="4"/>
      <inertia ixx="0.05" ixy="0" ixz="0" iyy="0.018" iyz="0" izz="0.044"/>
    </inertial>
    <visual>
      <origin rpy="0 0 0" xyz="0 0 0"/>
      <geometry>
        <mesh filename="package://laproscopic_grasper/meshes/iiwa14/visual/link_2.stl"/>
      </geometry>
      <material name="Orange"/>
    </visual>
    <collision>
      <origin rpy="0 0 0" xyz="0 0 0"/>
      <geometry>
        <mesh filename="package://laproscopic_grasper/meshes/iiwa14/collision/link_2.stl"/>
      </geometry>
      <material name="Orange"/>
    </collision>
  </link>
  <joint name="iiwa14_joint3" type="revolute">
    <parent link="iiwa14_link2"/>
    <child link="iiwa14_link3"/>
    <origin rpy="1.57079632679 0 3.14159265358" xyz="0 0.2045 0"/>
    <axis xyz="0 0 1"/>
    <limit effort="176" lower="-2.967" upper="2.967" velocity="1.7453"/>
  </joint>
  <link name="iiwa14_link3">
    <inertial>
      <origin rpy="0 0 0" xyz="0 0.03 0.13"/>
      <mass value="3"/>
      <inertia ixx="0.08" ixy="0" ixz="0" iyy="0.075" iyz="0" izz="0.01"/>
    </inertial>
    <visual>
      <origin rpy="0 0 0" xyz="0 0 0"/>
      <geometry>
        <mesh filename="package://laproscopic_grasper/meshes/iiwa14/visual/link_3.stl"/>
      </geometry>
      <material name="Orange"/>
    </visual>
    <collision>
      <origin rpy="0 0 0" xyz="0 0 0"/>
      <geometry>
        <mesh filename="package://laproscopic_grasper/meshes/iiwa14/collision/link_3.stl"/>
      </geometry>
      <material name="Orange"/>
    </collision>
  </link>
  <joint name="iiwa14_joint4" type="revolute">
    <parent link="iiwa14_link3"/>
    <child link="iiwa14_link4"/>
    <origin rpy="1.57079632679 0 0" xyz="0 0 0.2155"/>
    <axis xyz="0 0 1"/>
    <limit effort="176" lower="-2.0944" upper="2.0944" velocity="1.309"/>
  </joint>
  <link name="iiwa14_link4">
    <inertial>
      <origin rpy="0 0 0" xyz="0 0.067 0.034"/>
      <mass value="2.7"/>
      <inertia ixx="0.03" ixy="0" ixz="0" iyy="0.01" iyz="0" izz="0.029"/>
    </inertial>
    <visual>
      <origin rpy="0 0 0" xyz="0 0 0"/>
      <geometry>
        <mesh filename="package://laproscopic_grasper/meshes/iiwa14/visual/link_4.stl"/>
      </geometry>
      <material name="Orange"/>
    </visual>
    <collision>
      <origin rpy="0 0 0" xyz="0 0 0"/>
      <geometry>
        <mesh filename="package://laproscopic_grasper/meshes/iiwa14/collision/link_4.stl"/>
      </geometry>
      <material name="Orange"/>
    </collision>
  </link>
  <joint name="iiwa14_joint5" type="revolute">
    <parent link="iiwa14_link4"/>
    <child link="iiwa14_link5"/>
    <origin rpy="-1.57079632679 3.14159265358 0" xyz="0 0.1845 0"/>
    <axis xyz="0 0 1"/>
    <limit effort="110" lower="-2.967" upper="2.967" velocity="2.2689"/>
  </joint>
  <link name="iiwa14_link5">
    <inertial>
      <origin rpy="0 0 0" xyz="0.0001 0.021 0.076"/>
      <mass value="1.7"/>
      <inertia ixx="0.02" ixy="0" ixz="0" iyy="0.018" iyz="0" izz="0.005"/>
    </inertial>
    <visual>
      <origin rpy="0 0 0" xyz="0 0 0"/>
      <geometry>
        <mesh filename="package://laproscopic_grasper/meshes/iiwa14/visual/link_5.stl"/>
      </geometry>
      <material name="Orange"/>
    </visual>
    <collision>
      <origin rpy="0 0 0" xyz="0 0 0"/>
      <geometry>
        <mesh filename="package://laproscopic_grasper/meshes/iiwa14/collision/link_5.stl"/>
      </geometry>
      <material name="Orange"/>
    </collision>
  </link>
  <joint name="iiwa14_joint6" type="revolute">
    <parent link="iiwa14_link5"/>
    <child link="iiwa14_link6"/>
    <origin rpy="1.57079632679 0 0" xyz="0 0 0.2155"/>
    <axis xyz="0 0 1"/>
    <limit effort="40" lower="-2.0944" upper="2.0944" velocity="2.3562"/>
  </joint>
  <link name="iiwa14_link6">
    <inertial>
      <origin rpy="0 0 0" xyz="0 0.0006 0.0004"/>
      <mass value="1.8"/>
      <inertia ixx="0.005" ixy="0" ixz="0" iyy="0.0036" iyz="0" izz="0.0047"/>
    </inertial>
    <visual>
      <origin rpy="0 0 0" xyz="0 0 0"/>
      <geometry>
        <mesh filename="package://laproscopic_grasper/meshes/iiwa14/visual/link_6.stl"/>
      </geometry>
      <material name="Orange"/>
    </visual>
    <collision>
      <origin rpy="0 0 0" xyz="0 0 0"/>
      <geometry>
        <mesh filename="package://laproscopic_grasper/meshes/iiwa14/collision/link_6.stl"/>
      </geometry>
      <material name="Orange"/>
    </collision>
  </link>
  <joint name="iiwa14_joint7" type="revolute">
    <parent link="iiwa14_link6"/>
    <child link="iiwa14_link7"/>
    <origin rpy="-1.57079632679 3.14159265358 0" xyz="0 0.081 0"/>
    <axis xyz="0 0 1"/>
    <limit effort="40" lower="-3.0543" upper="3.0543" velocity="2.3562"/>
  </joint>
  <link name="iiwa14_link7">
    <inertial>
      <origin rpy="0 0 0" xyz="0 0 0.02"/>
      <mass value="0.3"/>
      <inertia ixx="0.001" ixy="0" ixz="0" iyy="0.001" iyz="0" izz="0.001"/>
    </inertial>
    <visual>
      <origin rpy="0 0 0" xyz="0 0 0"/>
      <geometry>
        <mesh filename="package://laproscopic_grasper/meshes/iiwa14/visual/link_7.stl"/>
      </geometry>
      <material name="Grey"/>
    </visual>
    <collision>
      <origin rpy="0 0 0" xyz="0 0 0"/>
      <geometry>
        <mesh filename="package://laproscopic_grasper/meshes/iiwa14/collision/link_7.stl"/>
      </geometry>
      <material name="Grey"/>
    </collision>
  </link>
  <joint name="iiwa14_joint8" type="fixed">
    <parent link="iiwa14_link7"/>
    <child link="iiwa14_link8"/>
    <origin rpy="0 0 0" xyz="0 0 0.045"/>
  </joint>
  <link name="iiwa14_link8">
    <inertial>
      <origin rpy="0 0 0" xyz="0 0 0"/>
      <mass value="1e-6"/>
      <inertia ixx="1" ixy="0" ixz="0" iyy="1" iyz="0" izz="1"/>
    </inertial>
  </link>
  <!-- ── Attachment ──────────────────────────────────────────────── -->
  <joint name="grasper_base_joint" type="fixed">
    <parent link="iiwa14_link8"/>
    <child link="grasper_adapter_link"/>
    <origin rpy="0 0 0" xyz="0 0 0.05"/>
  </joint>
  <link name="grasper_adapter_link">
    <visual>
      <origin rpy="0 0 0" xyz="0 0 0.012"/>
      <geometry>
        <cylinder length="0.024" radius="0.018"/>
      </geometry>
      <material name="adapter_gray">
        <color rgba="0.6 0.6 0.65 1"/>
      </material>
    </visual>
    <collision>
      <origin rpy="0 0 0" xyz="0 0 0.012"/>
      <geometry>
        <cylinder length="0.024" radius="0.018"/>
      </geometry>
    </collision>
    <inertial>
      <mass value="0.2"/>
      <inertia ixx="0.001" ixy="0" ixz="0" iyy="0.001" iyz="0" izz="0.001"/>
    </inertial>
  </link>
  <joint name="grasper_shaft_joint" type="fixed">
    <parent link="grasper_adapter_link"/>
    <child link="grasper_shaft"/>
    <origin rpy="0 0 0" xyz="0 0 0.024"/>
  </joint>
  <link name="grasper_shaft">
    <visual>
      <origin rpy="0 0 0" xyz="0 0 0.125"/>
      <geometry>
        <cylinder length="0.25" radius="0.005"/>
      </geometry>
      <material name="steel">
        <color rgba="0.8 0.8 0.8 1"/>
      </material>
    </visual>
    <collision>
      <origin rpy="0 0 0" xyz="0 0 0.125"/>
      <geometry>
        <cylinder length="0.25" radius="0.005"/>
      </geometry>
    </collision>
    <inertial>
      <mass value="0.5"/>
      <inertia ixx="0.01" ixy="0" ixz="0" iyy="0.01" iyz="0" izz="0.001"/>
    </inertial>
  </link>
  <!-- ── Wrist Pitch ─────────────────────────────────────────────── -->
  <joint name="grasper_pitch_joint" type="revolute">
    <parent link="grasper_shaft"/>
    <child link="tool_wrist_sca_link"/>
    <origin rpy="0 0 0" xyz="0 0 0.25"/>
    <axis xyz="0 1 0"/>
    <limit effort="200" lower="-1.5708" upper="1.5708" velocity="1.0"/>
    <dynamics damping="5.0" friction="0.5"/>
  </joint>
  <link name="tool_wrist_sca_link">
    <visual>
      <origin rpy="1.57079632679 3.14159265358 0" xyz="0.0051 0.0032 0"/>
      <geometry>
        <mesh filename="package://laproscopic_grasper/meshes/HighFidelity/tool_wrist_sca_link.stl" scale="1 1 1"/>
      </geometry>
    </visual>
    <visual>
      <origin rpy="0 0 0" xyz="0 0 0.005"/>
      <geometry>
        <sphere radius="0.008"/>
      </geometry>
      <material name="joint_red">
        <color rgba="1 0.2 0.2 1"/>
      </material>
    </visual>
    <collision>
      <origin rpy="0 0 0" xyz="0 0 0.005"/>
      <geometry>
        <sphere radius="0.01"/>
      </geometry>
    </collision>
    <inertial>
      <mass value="0.2"/>
      <inertia ixx="0.001" ixy="0" ixz="0" iyy="0.001" iyz="0" izz="0.001"/>
    </inertial>
  </link>
  <!-- ── Wrist Yaw ───────────────────────────────────────────────── -->
  <joint name="grasper_yaw_joint" type="revolute">
    <parent link="tool_wrist_sca_link"/>
    <child link="tool_wrist_sca_shaft_link"/>
    <origin rpy="0 0 0" xyz="0 0 0.01"/>
    <axis xyz="1 0 0"/>
    <limit effort="200" lower="-1.3963" upper="1.3963" velocity="1.0"/>
    <dynamics damping="5.0" friction="0.5"/>
  </joint>
  <link name="tool_wrist_sca_shaft_link">
    <visual>
      <origin rpy="0 0 0" xyz="0 -0.0002 -0.0025"/>
      <geometry>
        <mesh filename="package://laproscopic_grasper/meshes/HighFidelity/tool_wrist_sca_shaft_link.stl" scale="1 1 1"/>
      </geometry>
    </visual>
    <visual>
      <origin rpy="0 0 0" xyz="0 0 0.005"/>
      <geometry>
        <sphere radius="0.007"/>
      </geometry>
      <material name="joint_red"/>
    </visual>
    <collision>
      <origin rpy="0 0 0" xyz="0 0 0.005"/>
      <geometry>
        <sphere radius="0.01"/>
      </geometry>
    </collision>
    <inertial>
      <mass value="0.2"/>
      <inertia ixx="0.001" ixy="0" ixz="0" iyy="0.001" iyz="0" izz="0.001"/>
    </inertial>
  </link>
  <!-- ── Jaws (Two-Finger) ────────────────────────────────────────── -->
  <joint name="grasper_jaw_joint" type="revolute">
    <parent link="tool_wrist_sca_shaft_link"/>
    <child link="jaw_left_link"/>
    <origin rpy="0 0 0" xyz="0 0 0.01"/>
    <axis xyz="0 1 0"/>
    <limit effort="300" lower="0.0" upper="0.8" velocity="1.5"/>
    <dynamics damping="5.0" friction="0.5"/>
  </joint>
  <link name="jaw_left_link">
    <visual>
      <origin rpy="0 0 0" xyz="0 0 0"/>
      <geometry>
        <mesh filename="package://laproscopic_grasper/meshes/HighFidelity/tool_wrist_sca_ee_link_1.stl"/>
      </geometry>
    </visual>
    <visual>
      <origin rpy="0 0 0" xyz="0 0.002 0.02"/>
      <geometry>
        <box size="0.008 0.003 0.04"/>
      </geometry>
      <material name="jaw_steel">
        <color rgba="0.7 0.7 0.75 1"/>
      </material>
    </visual>
    <collision>
      <origin rpy="1.5708 0 0" xyz="0 0.002 0.02"/>
      <geometry>
        <cylinder length="0.04" radius="0.01"/>
      </geometry>
    </collision>
    <inertial>
      <origin xyz="0 0 0.02"/>
      <mass value="0.5"/>
      <inertia ixx="0.01" ixy="0" ixz="0" iyy="0.01" iyz="0" izz="0.01"/>
    </inertial>
  </link>
  <joint name="grasper_jaw_mimic_joint" type="revolute">
    <parent link="tool_wrist_sca_shaft_link"/>
    <child link="jaw_right_link"/>
    <origin rpy="0 0 0" xyz="0 0 0.01"/>
    <axis xyz="0 1 0"/>
    <limit effort="300" lower="-0.8" upper="0.0" velocity="1.5"/>
    <mimic joint="grasper_jaw_joint" multiplier="-1.0" offset="0.0"/>
    <dynamics damping="5.0" friction="0.5"/>
  </joint>
  <link name="jaw_right_link">
    <visual>
      <origin rpy="0 0 0" xyz="0 0 0"/>
      <geometry>
        <mesh filename="package://laproscopic_grasper/meshes/HighFidelity/tool_wrist_sca_ee_link_2.stl"/>
      </geometry>
    </visual>
    <visual>
      <origin rpy="0 0 0" xyz="0 -0.002 0.02"/>
      <geometry>
        <box size="0.008 0.003 0.04"/>
      </geometry>
      <material name="jaw_steel"/>
    </visual>
    <collision>
      <origin rpy="1.5708 0 0" xyz="0 -0.002 0.02"/>
      <geometry>
        <cylinder length="0.04" radius="0.01"/>
      </geometry>
    </collision>
    <inertial>
      <origin xyz="0 0 0.02"/>
      <mass value="0.5"/>
      <inertia ixx="0.01" ixy="0" ixz="0" iyy="0.01" iyz="0" izz="0.01"/>
    </inertial>
  </link>
  <gazebo reference="jaw_left_link">
    <mu1>2.0</mu1>
    <mu2>2.0</mu2>
    <kp>1000000.0</kp>
    <kd>50.0</kd>
  </gazebo>
  <gazebo reference="jaw_right_link">
    <mu1>2.0</mu1>
    <mu2>2.0</mu2>
    <kp>1000000.0</kp>
    <kd>50.0</kd>
  </gazebo>
  <!-- ================================================================== -->
  <!--  ROS2 CONTROL                                                      -->
  <!-- ================================================================== -->
  <ros2_control name="kuka_laproscopic_grasper_system" type="system">
    <hardware>
      <plugin>gz_ros2_control/GazeboSimSystem</plugin>
    </hardware>
    <!-- ==== KUKA Arm joints ==== -->
    <joint name="iiwa14_joint1">
      <command_interface name="position"/>
      <state_interface name="position">
        <param name="initial_value">0.0</param>
      </state_interface>
      <state_interface name="velocity"/>
      <state_interface name="effort"/>
    </joint>
    <joint name="iiwa14_joint2">
      <command_interface name="position"/>
      <state_interface name="position">
        <param name="initial_value">0.0</param>
      </state_interface>
      <state_interface name="velocity"/>
      <state_interface name="effort"/>
    </joint>
    <joint name="iiwa14_joint3">
      <command_interface name="position"/>
      <state_interface name="position">
        <param name="initial_value">0.0</param>
      </state_interface>
      <state_interface name="velocity"/>
      <state_interface name="effort"/>
    </joint>
    <joint name="iiwa14_joint4">
      <command_interface name="position"/>
      <state_interface name="position">
        <param name="initial_value">0.0</param>
      </state_interface>
      <state_interface name="velocity"/>
      <state_interface name="effort"/>
    </joint>
    <joint name="iiwa14_joint5">
      <command_interface name="position"/>
      <state_interface name="position">
        <param name="initial_value">0.0</param>
      </state_interface>
      <state_interface name="velocity"/>
      <state_interface name="effort"/>
    </joint>
    <joint name="iiwa14_joint6">
      <command_interface name="position"/>
      <state_interface name="position">
        <param name="initial_value">0.0</param>
      </state_interface>
      <state_interface name="velocity"/>
      <state_interface name="effort"/>
    </joint>
    <joint name="iiwa14_joint7">
      <command_interface name="position"/>
      <state_interface name="position">
        <param name="initial_value">0.0</param>
      </state_interface>
      <state_interface name="velocity"/>
      <state_interface name="effort"/>
    </joint>
    <!-- ==== Grasper joints (Merged) ==== -->
    <joint name="grasper_pitch_joint">
      <command_interface name="position"/>
      <state_interface name="position">
        <param name="initial_value">0.0</param>
      </state_interface>
      <state_interface name="velocity"/>
    </joint>
    <joint name="grasper_yaw_joint">
      <command_interface name="position"/>
      <state_interface name="position">
        <param name="initial_value">0.0</param>
      </state_interface>
      <state_interface name="velocity"/>
    </joint>
    <joint name="grasper_jaw_joint">
      <command_interface name="position"/>
      <state_interface name="position">
        <param name="initial_value">0.8</param>
      </state_interface>
      <state_interface name="velocity"/>
    </joint>
  </ros2_control>
  <!-- ================================================================== -->
  <!--  GAZEBO PLUGINS                                                    -->
  <!-- ================================================================== -->
  <!-- The config_path shouldn't be overridden if the launch file passes it or launch injects plugin block -->
  <!-- We'll keep the template simple, launch file will inject its own plugin parameters if needed. -->
  <gazebo>
    <plugin filename="gz_ros2_control-system" name="gz_ros2_control::GazeboSimROS2ControlPlugin">
      <parameters></parameters>
    </plugin>
  </gazebo>
  <!-- Force/Torque sensor on trocar shaft (mounted at shaft/wrist junction) -->
  <gazebo reference="grasper_pitch_joint">
    <sensor name="shaft_force_torque" type="force_torque">
      <always_on>true</always_on>
      <update_rate>100</update_rate>
      <topic>shaft_force_torque</topic>
    </sensor>
  </gazebo>
  <!-- Contact sensors on jaw tips -->
  <!-- Contact sensors on jaw tips -->
  <gazebo reference="jaw_left_link">
    <sensor name="jaw_left_contact" type="contact">
      <always_on>true</always_on>
      <update_rate>50</update_rate>
      <contact>
        <collision>jaw_left_link_collision</collision>
      </contact>
      <topic>jaw_left_contact</topic>
    </sensor>
  </gazebo>
  <gazebo reference="jaw_right_link">
    <sensor name="jaw_right_contact" type="contact">
      <always_on>true</always_on>
      <update_rate>50</update_rate>
      <contact>
        <collision>jaw_right_link_collision</collision>
      </contact>
      <topic>jaw_right_contact</topic>
    </sensor>
  </gazebo>
</robot>
